<?xml version="1.0"?>
<sdf version="1.6">
    <model name="capra_robot">
        <!-- Set model ignored or not by physics engine -->
        <static>false</static>

        <link name='base_link'>
            <pose>0 0 .1 0 0 0</pose>

            <collision name='collision'>
                <geometry>
                    <box>
                        <size>.4 .2 .1</size>
                    </box>
                </geometry>
            </collision>

            <visual name='visual'>
                <geometry>
                    <box>
                        <size>.4 .2 .1</size>
                    </box>
                </geometry>
            </visual>

            <collision name='caster_collision'>
                <pose>-0.15 0 -0.05 0 0 0</pose>

                <geometry>
                    <sphere>
                        <radius>.05</radius>
                    </sphere>
                </geometry>

                <surface>
                    <friction>
                        <ode>
                            <mu>0</mu>
                            <mu2>0</mu2>
                            <slip1>1.0</slip1>
                            <slip2>1.0</slip2>
                        </ode>
                    </friction>
                </surface>
            </collision>

            <visual name='caster_visual'>
                <pose>-0.15 0 -0.05 0 0 0</pose>

                <geometry>
                    <sphere>
                        <radius>.05</radius>
                    </sphere>
                </geometry>
            </visual>
        </link>

        <link name="laser">
            <pose>0.195 0 0.16 0 0 0</pose>

            <collision name="collision">
                <geometry>
                    <box>
                        <size>.01 .01 .1</size>
                    </box>
                </geometry>
            </collision>

            <visual name='visual'>
                <geometry>
                    <box>
                        <size>.01 .01 .1</size>
                    </box>
                </geometry>
            </visual>

            <sensor name='LIDAR' type='ray'>
                <visualize>1</visualize>
                <update_rate>30</update_rate>
                <ray>
                    <scan>
                        <horizontal>
                        <samples>540</samples>
                        <resolution>1</resolution>
                        <min_angle>-2.3562</min_angle>
                        <max_angle>2.3562</max_angle>
                        </horizontal>
                        <vertical>
                        <samples>1</samples>
                        <min_angle>0</min_angle>
                        <max_angle>0</max_angle>
                        </vertical>
                    </scan>
                    <range>
                        <min>0.2</min>
                        <max>4</max>
                        <resolution>0.1</resolution>
                    </range>
                    <noise>
                        <type>gaussian</type>
                        <mean>0</mean>
                        <stddev>0.01</stddev>
                    </noise>
                </ray>

                <plugin name='laser' filename='libgazebo_ros_laser.so'>
                    <topicName>/LaserScan</topicName>
                    <frameName>laser</frameName>
                    <robotNamespace>/capra_simulation/</robotNamespace>
                </plugin>

                <always_on>1</always_on>
                <update_rate>5</update_rate>
                <visualize>1</visualize>
                <pose>0 0 0.05 0 0 0</pose>
            </sensor>
        </link>

        <joint type="fixed" name="sensor_tower">
            <pose>0 0 0 0 0 0</pose>

            <child>laser</child>
            <parent>base_link</parent>

            <axis>
                <xyz>0 0 1</xyz>
            </axis>
        </joint>

        <link name="right_wheel_back">
            <pose>-0.15 -0.14 0.1 0 1.5707 1.5707</pose>
            
            <collision name="collision">
                <geometry>
                    <cylinder>
                        <radius>.1</radius>
                        <length>.05</length>
                    </cylinder>
                </geometry>
            </collision>
            
            <visual name="visual">
                <geometry>
                    <cylinder>
                        <radius>.1</radius>
                        <length>.05</length>
                    </cylinder>
                </geometry>
            </visual>
        </link>

        <link name="left_wheel_back">
            <pose>-0.15 0.14 0.1 0 1.5707 1.5707</pose>

            <collision name="collision">
                <geometry>
                    <cylinder>
                    <radius>.1</radius>
                    <length>.05</length>
                    </cylinder>
                </geometry>
            </collision>
            
            <visual name="visual">
                <geometry>
                    <cylinder>
                    <radius>.1</radius>
                    <length>.05</length>
                    </cylinder>
                </geometry>
            </visual>
        </link>

        <joint type="revolute" name="right_wheel_front_hinge">
            <pose>0 0 -0.03 0 0 0</pose>

            <child>right_wheel_front</child>
            <parent>base_link</parent>

            <axis>
                <xyz>0 1 0</xyz>
            </axis>
        </joint>

        <joint type="revolute" name="left_wheel_front_hinge">
            <pose>0 0 0.03 0 0 0</pose>

            <child>left_wheel_front</child>
            <parent>base_link</parent>
            
            <axis>
                <xyz>0 1 0</xyz>
            </axis>
        </joint>

        <link name="left_wheel_front">
            <pose>0.15 0.14 0.1 0 1.5707 1.5707</pose>
            
            <collision name="collision">
                <geometry>
                    <cylinder>
                        <radius>.1</radius>
                        <length>.05</length>
                    </cylinder>
                </geometry>
            </collision>
            
            <visual name="visual">
                <geometry>
                    <cylinder>
                        <radius>.1</radius>
                        <length>.05</length>
                    </cylinder>
                </geometry>
            </visual>
        </link>

        <link name="right_wheel_front">
            <pose>0.15 -0.14 0.1 0 1.5707 1.5707</pose>

            <collision name="collision">
                <geometry>
                    <cylinder>
                    <radius>.1</radius>
                    <length>.05</length>
                    </cylinder>
                </geometry>
            </collision>
            
            <visual name="visual">
                <geometry>
                    <cylinder>
                    <radius>.1</radius>
                    <length>.05</length>
                    </cylinder>
                </geometry>
            </visual>
        </link>

        <joint type="revolute" name="right_wheel_back_hinge">
            <pose>0 0 -0.03 0 0 0</pose>

            <child>right_wheel_back</child>
            <parent>base_link</parent>

            <axis>
                <xyz>0 1 0</xyz>
            </axis>
        </joint>

        <joint type="revolute" name="left_wheel_back_hinge">
            <pose>0 0 0.03 0 0 0</pose>

            <child>left_wheel_back</child>
            <parent>base_link</parent>
            
            <axis>
                <xyz>0 1 0</xyz>
            </axis>
        </joint>

    </model>
</sdf>